<mujoco model="magni">
    <compiler angle="radian" meshdir="./assets" />
    <option timestep="0.002" integrator="implicitfast" />

    <default>
        <default class="visual">
            <geom type="mesh" contype="0" conaffinity="0" group="2" density="0" />
        </default>
        <default class="collision">
            <geom group="3" />
        </default>
        <default class="wheel">
            <joint type="hinge" axis="1 0 0" damping="0.1"
                armature="0.005" frictionloss="0.05" />
        </default>
    </default>

    <asset>
        <material name="chassis_light"    rgba="0.7922 0.8196 0.9333 1.0000" />
        <material name="accent_navy"      rgba="0.0000 0.0000 0.3765 1.0000" />
        <material name="hubcap_dark"      rgba="0.1373 0.1373 0.1373 1.0000" />
        <material name="axlecap_grey"     rgba="0.5020 0.5020 0.5020 1.0000" />
        <material name="body_black"       rgba="0.0588 0.0588 0.0863 1.0000" />
        <material name="body_blue"        rgba="0.0039 0.1216 0.4196 1.0000" />
        <material name="body_blue_dark"   rgba="0.0039 0.1294 0.2275 1.0000" />
        <material name="sonar_pcb"        rgba="0.0000 0.0000 0.5020 1.0000" />
        <material name="sonar_housing"    rgba="0.6667 0.6980 0.7686 1.0000" />
        <material name="sonar_led"        rgba="0.1373 0.2941 0.7490 1.0000" />
        <material name="sonar_chip"       rgba="0.0706 0.0706 0.0706 1.0000" />
        <material name="sonar_transducer" rgba="0.8941 0.9137 0.9294 1.0000" />

        <mesh name="caster_wheel__0" file="parts/caster_wheel__0.stl" inertia="shell" />
        <mesh name="caster_wheel__1" file="parts/caster_wheel__1.stl" inertia="shell" />
        <mesh name="caster_wheel__2" file="parts/caster_wheel__2.stl" inertia="shell" />
        <mesh name="caster_wheel__3" file="parts/caster_wheel__3.stl" inertia="shell" />
        <mesh name="caster_wheel__4" file="parts/caster_wheel__4.stl" inertia="shell" />
        <mesh name="caster_wheel__5" file="parts/caster_wheel__5.stl" inertia="shell" />
        <mesh name="front_wheel__0" file="parts/front_wheel__0.stl" inertia="shell" />
        <mesh name="front_wheel__1" file="parts/front_wheel__1.stl" inertia="shell" />
        <mesh name="front_wheel__2" file="parts/front_wheel__2.stl" inertia="shell" />
        <mesh name="magni_body__0" file="parts/magni_body__0.stl" inertia="shell" />
        <mesh name="magni_body__1" file="parts/magni_body__1.stl" inertia="shell" />
        <mesh name="magni_body__2" file="parts/magni_body__2.stl" inertia="shell" />
        <mesh name="magni_body__3" file="parts/magni_body__3.stl" inertia="shell" />
        <mesh name="magni_body__4" file="parts/magni_body__4.stl" inertia="shell" />
        <mesh name="sonar_hc-sr04__0" file="parts/sonar_hc-sr04__0.stl" inertia="shell" />
        <mesh name="sonar_hc-sr04__1" file="parts/sonar_hc-sr04__1.stl" inertia="shell" />
        <mesh name="sonar_hc-sr04__2" file="parts/sonar_hc-sr04__2.stl" inertia="shell" />
        <mesh name="sonar_hc-sr04__3" file="parts/sonar_hc-sr04__3.stl" inertia="shell" />
        <mesh name="sonar_hc-sr04__4" file="parts/sonar_hc-sr04__4.stl" inertia="shell" />
    </asset>

    <worldbody>
        <body name="base" pos="0 0 0.1">
            <freejoint />
            <inertial pos="-0.15 0 0.03" quat="0 0.707107 0 0.707107" mass="10"
                diaginertia="0.172704 0.150753 0.0594508" />
            <site name="imu" pos="0 0 0" size="0.01" rgba="1 0 0 0.5" />
            <body name="body" pos="-0.11 0 -0.029" quat="1 0 0 0">
                <inertial pos="-0.03 0 0.11" mass="1.0"
                    diaginertia="0.02 0.025 0.03" />
                <geom class="collision" type="box" pos="-0.03 0 0.11"
                    size="0.2 0.11 0.05" />
                <geom class="visual" mesh="magni_body__0" material="body_black" />
                <geom class="visual" mesh="magni_body__1" material="body_blue" />
                <geom class="visual" mesh="magni_body__2" material="body_blue" />
                <geom class="visual" mesh="magni_body__3" material="body_blue_dark" />
                <geom class="visual" mesh="magni_body__4" material="body_blue" />
            </body>
            <body name="left_caster_yoke" pos="-0.279 0.17 -0.01" quat="0 0 0 1">
                <inertial pos="0 0 -0.025" mass="0.15"
                    diaginertia="1e-4 1e-4 1e-4" />
                <joint name="left_caster_swivel" type="hinge" axis="0 0 1"
                    damping="0.005" />
                <geom class="visual" mesh="caster_wheel__0" material="chassis_light" />
                <geom class="visual" mesh="caster_wheel__1" material="chassis_light" />
                <geom class="visual" mesh="caster_wheel__2" material="chassis_light" />
                <geom class="visual" mesh="caster_wheel__3" material="chassis_light" />
                <geom class="visual" mesh="caster_wheel__4" material="accent_navy" />
                <geom class="visual" mesh="caster_wheel__5" material="chassis_light" />
                <body name="left_caster_wheel" pos="0.025 0 -0.05">
                    <inertial pos="0 0 0" mass="0.05"
                        diaginertia="3e-5 3e-5 3e-5" />
                    <joint name="left_caster_roll" type="hinge" axis="0 1 0"
                        damping="0.001" />
                    <geom class="collision" type="sphere" size="0.04"
                        friction="1 0.005 0.0001" />
                </body>
            </body>
            <body name="right_caster_yoke" pos="-0.279 -0.17 -0.01" quat="0 0 0 1">
                <inertial pos="0 0 -0.025" mass="0.15"
                    diaginertia="1e-4 1e-4 1e-4" />
                <joint name="right_caster_swivel" type="hinge" axis="0 0 1"
                    damping="0.005" />
                <geom class="visual" mesh="caster_wheel__0" material="chassis_light" />
                <geom class="visual" mesh="caster_wheel__1" material="chassis_light" />
                <geom class="visual" mesh="caster_wheel__2" material="chassis_light" />
                <geom class="visual" mesh="caster_wheel__3" material="chassis_light" />
                <geom class="visual" mesh="caster_wheel__4" material="accent_navy" />
                <geom class="visual" mesh="caster_wheel__5" material="chassis_light" />
                <body name="right_caster_wheel" pos="0.025 0 -0.05">
                    <inertial pos="0 0 0" mass="0.05"
                        diaginertia="3e-5 3e-5 3e-5" />
                    <joint name="right_caster_roll" type="hinge" axis="0 1 0"
                        damping="0.001" />
                    <geom class="collision" type="sphere" size="0.04"
                        friction="1 0.005 0.0001" />
                </body>
            </body>
            <body name="left_front_wheel" pos="0 0.163 0" quat="0.707107 0 0 0.707107">
                <inertial pos="0 0 0" quat="0.5 0.5 -0.5 0.5" mass="3.34"
                    diaginertia="0.0167 0.00904583 0.00904583" />
                <joint class="wheel" name="left_wheel_joint" />
                <geom class="collision" type="cylinder" size="0.1"
                    fromto="-0.025 0 0 0.025 0 0" />
                <geom class="visual" pos="-0.071 0 0" mesh="front_wheel__0"
                    material="chassis_light" />
                <geom class="visual" pos="-0.071 0 0" mesh="front_wheel__1"
                    material="hubcap_dark" />
                <geom class="visual" pos="-0.071 0 0" mesh="front_wheel__2"
                    material="axlecap_grey" />
            </body>
            <body name="right_front_wheel" pos="0 -0.163 0" quat="0.707107 0 0 0.707107">
                <inertial pos="0 0 0" quat="0.5 0.5 -0.5 0.5" mass="3.34"
                    diaginertia="0.0167 0.00904583 0.00904583" />
                <joint class="wheel" name="right_wheel_joint" />
                <geom class="collision" type="cylinder" size="0.1"
                    fromto="-0.025 0 0 0.025 0 0" />
                <geom class="visual" pos="0.071 0 0" quat="0 0 -1 0" mesh="front_wheel__0"
                    material="chassis_light" />
                <geom class="visual" pos="0.071 0 0" quat="0 0 -1 0" mesh="front_wheel__1"
                    material="hubcap_dark" />
                <geom class="visual" pos="0.071 0 0" quat="0 0 -1 0" mesh="front_wheel__2"
                    material="axlecap_grey" />
            </body>
            <body name="sonar_0" pos="0.01 -0.14 0.15" quat="0.707107 0 0 -0.707107">
                <inertial pos="0 0 0" mass="0.01"
                    diaginertia="1e-6 2e-6 2e-6" />
                <site name="sonar_0_site" pos="0.015 0 0" zaxis="1 0 0"
                    size="0.005" rgba="0 1 0 0.5" />
                <geom class="visual" pos="-0.006 0 0" quat="0.5 0.5 0.5 0.5" mesh="sonar_hc-sr04__0"
                    material="sonar_pcb" />
                <geom class="visual" pos="-0.006 0 0" quat="0.5 0.5 0.5 0.5" mesh="sonar_hc-sr04__1"
                    material="sonar_housing" />
                <geom class="visual" pos="-0.006 0 0" quat="0.5 0.5 0.5 0.5" mesh="sonar_hc-sr04__2"
                    material="sonar_led" />
                <geom class="visual" pos="-0.006 0 0" quat="0.5 0.5 0.5 0.5" mesh="sonar_hc-sr04__3"
                    material="sonar_chip" />
                <geom class="visual" pos="-0.006 0 0" quat="0.5 0.5 0.5 0.5" mesh="sonar_hc-sr04__4"
                    material="sonar_transducer" />
            </body>
            <body name="sonar_1" pos="0.08 -0.07 0.15" quat="0.923956 0 0 0.382499">
                <inertial pos="0 0 0" mass="0.01"
                    diaginertia="1e-6 2e-6 2e-6" />
                <site name="sonar_1_site" pos="0.015 0 0" zaxis="1 0 0"
                    size="0.005" rgba="0 1 0 0.5" />
                <geom class="visual" pos="-0.006 0 0" quat="0.5 0.5 0.5 0.5" mesh="sonar_hc-sr04__0"
                    material="sonar_pcb" />
                <geom class="visual" pos="-0.006 0 0" quat="0.5 0.5 0.5 0.5" mesh="sonar_hc-sr04__1"
                    material="sonar_housing" />
                <geom class="visual" pos="-0.006 0 0" quat="0.5 0.5 0.5 0.5" mesh="sonar_hc-sr04__2"
                    material="sonar_led" />
                <geom class="visual" pos="-0.006 0 0" quat="0.5 0.5 0.5 0.5" mesh="sonar_hc-sr04__3"
                    material="sonar_chip" />
                <geom class="visual" pos="-0.006 0 0" quat="0.5 0.5 0.5 0.5" mesh="sonar_hc-sr04__4"
                    material="sonar_transducer" />
            </body>
            <body name="sonar_2" pos="0.08 -0.01 0.15" quat="0.923956 0 0 -0.382499">
                <inertial pos="0 0 0" mass="0.01"
                    diaginertia="1e-6 2e-6 2e-6" />
                <site name="sonar_2_site" pos="0.015 0 0" zaxis="1 0 0"
                    size="0.005" rgba="0 1 0 0.5" />
                <geom class="visual" pos="-0.006 0 0" quat="0.5 0.5 0.5 0.5" mesh="sonar_hc-sr04__0"
                    material="sonar_pcb" />
                <geom class="visual" pos="-0.006 0 0" quat="0.5 0.5 0.5 0.5" mesh="sonar_hc-sr04__1"
                    material="sonar_housing" />
                <geom class="visual" pos="-0.006 0 0" quat="0.5 0.5 0.5 0.5" mesh="sonar_hc-sr04__2"
                    material="sonar_led" />
                <geom class="visual" pos="-0.006 0 0" quat="0.5 0.5 0.5 0.5" mesh="sonar_hc-sr04__3"
                    material="sonar_chip" />
                <geom class="visual" pos="-0.006 0 0" quat="0.5 0.5 0.5 0.5" mesh="sonar_hc-sr04__4"
                    material="sonar_transducer" />
            </body>
            <body name="sonar_3" pos="0.08 0.04 0.15">
                <inertial pos="0 0 0" mass="0.01"
                    diaginertia="1e-6 2e-6 2e-6" />
                <site name="sonar_3_site" pos="0.015 0 0" zaxis="1 0 0"
                    size="0.005" rgba="0 1 0 0.5" />
                <geom class="visual" pos="-0.006 0 0" quat="0.5 0.5 0.5 0.5" mesh="sonar_hc-sr04__0"
                    material="sonar_pcb" />
                <geom class="visual" pos="-0.006 0 0" quat="0.5 0.5 0.5 0.5" mesh="sonar_hc-sr04__1"
                    material="sonar_housing" />
                <geom class="visual" pos="-0.006 0 0" quat="0.5 0.5 0.5 0.5" mesh="sonar_hc-sr04__2"
                    material="sonar_led" />
                <geom class="visual" pos="-0.006 0 0" quat="0.5 0.5 0.5 0.5" mesh="sonar_hc-sr04__3"
                    material="sonar_chip" />
                <geom class="visual" pos="-0.006 0 0" quat="0.5 0.5 0.5 0.5" mesh="sonar_hc-sr04__4"
                    material="sonar_transducer" />
            </body>
            <body name="sonar_4" pos="0.01 0.14 0.15" quat="0.707107 0 0 0.707107">
                <inertial pos="0 0 0" mass="0.01"
                    diaginertia="1e-6 2e-6 2e-6" />
                <site name="sonar_4_site" pos="0.015 0 0" zaxis="1 0 0"
                    size="0.005" rgba="0 1 0 0.5" />
                <geom class="visual" pos="-0.006 0 0" quat="0.5 0.5 0.5 0.5" mesh="sonar_hc-sr04__0"
                    material="sonar_pcb" />
                <geom class="visual" pos="-0.006 0 0" quat="0.5 0.5 0.5 0.5" mesh="sonar_hc-sr04__1"
                    material="sonar_housing" />
                <geom class="visual" pos="-0.006 0 0" quat="0.5 0.5 0.5 0.5" mesh="sonar_hc-sr04__2"
                    material="sonar_led" />
                <geom class="visual" pos="-0.006 0 0" quat="0.5 0.5 0.5 0.5" mesh="sonar_hc-sr04__3"
                    material="sonar_chip" />
                <geom class="visual" pos="-0.006 0 0" quat="0.5 0.5 0.5 0.5" mesh="sonar_hc-sr04__4"
                    material="sonar_transducer" />
            </body>
        </body>
    </worldbody>

    <contact>
        <exclude body1="body" body2="left_front_wheel" />
        <exclude body1="body" body2="right_front_wheel" />
        <exclude body1="body" body2="left_caster_yoke" />
        <exclude body1="body" body2="right_caster_yoke" />
        <exclude body1="body" body2="left_caster_wheel" />
        <exclude body1="body" body2="right_caster_wheel" />
    </contact>

    <actuator>
        <velocity name="left_wheel"  joint="left_wheel_joint"  kv="10" ctrlrange="-10 10" />
        <velocity name="right_wheel" joint="right_wheel_joint" kv="10" ctrlrange="-10 10" />
    </actuator>

    <keyframe>
        <key name="home"
            qpos="0 0 0.0998  1 0 0 0  0 0  0 0  0 0" />
    </keyframe>

    <sensor>
        <gyro          name="imu_gyro"        site="imu" />
        <accelerometer name="imu_acc"         site="imu" />
        <framepos      name="base_pos"        objtype="site" objname="imu" />
        <framequat     name="base_quat"       objtype="site" objname="imu" />
        <jointpos      name="left_wheel_pos"  joint="left_wheel_joint" />
        <jointpos      name="right_wheel_pos" joint="right_wheel_joint" />
        <jointvel      name="left_wheel_vel"  joint="left_wheel_joint" />
        <jointvel      name="right_wheel_vel" joint="right_wheel_joint" />
        <rangefinder   name="sonar_0" site="sonar_0_site" cutoff="4" />
        <rangefinder   name="sonar_1" site="sonar_1_site" cutoff="4" />
        <rangefinder   name="sonar_2" site="sonar_2_site" cutoff="4" />
        <rangefinder   name="sonar_3" site="sonar_3_site" cutoff="4" />
        <rangefinder   name="sonar_4" site="sonar_4_site" cutoff="4" />
    </sensor>
</mujoco>
